Traceback (most recent call last):
  File "/opt/anaconda3/envs/qe-mini-example/lib/python3.7/site-packages/jupyter_cache/executors/utils.py", line 56, in single_nb_execution
    record_timing=False,
  File "/opt/anaconda3/envs/qe-mini-example/lib/python3.7/site-packages/nbclient/client.py", line 1082, in execute
    return NotebookClient(nb=nb, resources=resources, km=km, **kwargs).execute()
  File "/opt/anaconda3/envs/qe-mini-example/lib/python3.7/site-packages/nbclient/util.py", line 74, in wrapped
    return just_run(coro(*args, **kwargs))
  File "/opt/anaconda3/envs/qe-mini-example/lib/python3.7/site-packages/nbclient/util.py", line 53, in just_run
    return loop.run_until_complete(coro)
  File "/opt/anaconda3/envs/qe-mini-example/lib/python3.7/asyncio/base_events.py", line 587, in run_until_complete
    return future.result()
  File "/opt/anaconda3/envs/qe-mini-example/lib/python3.7/site-packages/nbclient/client.py", line 536, in async_execute
    cell, index, execution_count=self.code_cells_executed + 1
  File "/opt/anaconda3/envs/qe-mini-example/lib/python3.7/site-packages/nbclient/client.py", line 827, in async_execute_cell
    self._check_raise_for_error(cell, exec_reply)
  File "/opt/anaconda3/envs/qe-mini-example/lib/python3.7/site-packages/nbclient/client.py", line 735, in _check_raise_for_error
    raise CellExecutionError.from_cell_and_msg(cell, exec_reply['content'])
nbclient.exceptions.CellExecutionError: An error occurred while executing the following cell:
------------------
from sklearn import datasets
import matplotlib.pyplot as plt
 
#加载数据集，是一个字典类似Java中的map
lris_df = datasets.load_iris()
lris_df.head()
------------------

[0;31m---------------------------------------------------------------------------[0m
[0;31mKeyError[0m                                  Traceback (most recent call last)
[0;32m/opt/anaconda3/envs/qe-mini-example/lib/python3.7/site-packages/sklearn/utils/__init__.py[0m in [0;36m__getattr__[0;34m(self, key)[0m
[1;32m     95[0m         [0;32mtry[0m[0;34m:[0m[0;34m[0m[0;34m[0m[0m
[0;32m---> 96[0;31m             [0;32mreturn[0m [0mself[0m[0;34m[[0m[0mkey[0m[0;34m][0m[0;34m[0m[0;34m[0m[0m
[0m[1;32m     97[0m         [0;32mexcept[0m [0mKeyError[0m[0;34m:[0m[0;34m[0m[0;34m[0m[0m

[0;31mKeyError[0m: 'head'

During handling of the above exception, another exception occurred:

[0;31mAttributeError[0m                            Traceback (most recent call last)
[0;32m<ipython-input-2-91466de3906c>[0m in [0;36m<module>[0;34m[0m
[1;32m      4[0m [0;31m#加载数据集，是一个字典类似Java中的map[0m[0;34m[0m[0;34m[0m[0;34m[0m[0m
[1;32m      5[0m [0mlris_df[0m [0;34m=[0m [0mdatasets[0m[0;34m.[0m[0mload_iris[0m[0;34m([0m[0;34m)[0m[0;34m[0m[0;34m[0m[0m
[0;32m----> 6[0;31m [0mlris_df[0m[0;34m.[0m[0mhead[0m[0;34m([0m[0;34m)[0m[0;34m[0m[0;34m[0m[0m
[0m
[0;32m/opt/anaconda3/envs/qe-mini-example/lib/python3.7/site-packages/sklearn/utils/__init__.py[0m in [0;36m__getattr__[0;34m(self, key)[0m
[1;32m     96[0m             [0;32mreturn[0m [0mself[0m[0;34m[[0m[0mkey[0m[0;34m][0m[0;34m[0m[0;34m[0m[0m
[1;32m     97[0m         [0;32mexcept[0m [0mKeyError[0m[0;34m:[0m[0;34m[0m[0;34m[0m[0m
[0;32m---> 98[0;31m             [0;32mraise[0m [0mAttributeError[0m[0;34m([0m[0mkey[0m[0;34m)[0m[0;34m[0m[0;34m[0m[0m
[0m[1;32m     99[0m [0;34m[0m[0m
[1;32m    100[0m     [0;32mdef[0m [0m__setstate__[0m[0;34m([0m[0mself[0m[0;34m,[0m [0mstate[0m[0;34m)[0m[0;34m:[0m[0;34m[0m[0;34m[0m[0m

[0;31mAttributeError[0m: head
AttributeError: head

